Workbook

Sheet 1 - Original Dataset
A1: ORIGINAL DATASET - 24 Files
A2: File ID | B2: File Name | C2: File Type | D2: File Size (MB) | E2: SHA-256 Hash
A3: 1 | B3: docx1.docx | C3: docx | D3: 3.4462 | E3: 0b10fed99d7889f89a158e1057ed5c9719f7975626be297dfd2f774532e70421
A4: 2 | B4: docx2.docx | C4: docx | D4: 32.1414 | E4: ae2cef007d681624ef0f00b7c745bda52f76f7b5a31a55001e20d630d94a2278
A5: 3 | B5: docx3.docx | C5: docx | D5: 12.421 | E5: 09be14b572b6bce4a19bd30d7789a8a8fa240188ee992cd3cadefb31f299950a
A6: 4 | B6: docx4.docx | C6: docx | D6: 89.5601 | E6: a6f55325d7e3bd441e9d08671961394ebb4a055f2d8febf0937e8a72b5bc13e3
A7: 5 | B7: jpg1.jpg | C7: jpg | D7: 6.1822 | E7: 45dd659209929665ebdf6d670130a18e7818daf12e2fdb844d1c613dda11a2c8
A8: 6 | B8: jpg2.jpg | C8: jpg | D8: 4.5278 | E8: d39e9d800bd621bdc27564fc82d09e6af602696688f7607a62c1ee7877730c73
A9: 7 | B9: jpg3.jpg | C9: jpg | D9: 3.6108 | E9: 8573f63bf67538ba97afb254849071125e2e0c8397bae75ce7aecbbf43c6fa85
A10: 8 | B10: jpg4.jpg | C10: jpg | D10: 2.8071 | E10: 6b3b678cb4c25e0991c5047d732c158f3d0989f9b2137bf40d49f285e6caccd6
A11: 9 | B11: jpg5.jpg | C11: jpg | D11: 7.4454 | E11: 760c4b1a4a22602d762df6fcea43ef972e87d2e5e3d8f3f3a095bc47b3ad261f
A12: 10 | B12: jpg6.jpg | C12: jpg | D12: 2.4026 | E12: 82ea6696f670c009af187d0670a3752e5c6ff266f4ebbed7c58d446e66eaf847
A13: 11 | B13: mp4-1.mp4 | C13: mp4 | D13: 250.8668 | E13: 7ac0052c9b679ba18426c39ee60988d1e376d423c79ddecb3a1ee87eb84f7217
A14: 12 | B14: mp4-2.mp4 | C14: mp4 | D14: 68.5231 | E14: ae0b6d5ae2d87d11d346d775f29596c4f55d984851d2cc9cc6ff5b9ba1c8d569
... A26: 24 | B26: png4.png | C26: png | D26: 17.9744 | E26: 33dbd173890531cd6b77a9e7e0ccb79bb8ddd949aa936c1979eece075ae6d4de

Sheet 2 - Foremost S1
A1: Foremost - Scenario 1 - Normal Deletion
A2: # | B2: Recovered File Name | C2: File Type | D2: Size (MB) | E2: SHA-256 Hash | F2: Match? (Yes/No) | G2: Status | H2: Processing Time (sec)
A3: 1 | B3: 00034848.docx | C3: docx | D3: 32.14 | E3: AE2CEF007D681624EF0F00B7C745BDA52F76F7B5A31A55001E20D630D94A2278 | F3: Yes | G3: valid | H3: 75.37s
A4: 2 | B4: 00100680.docx | C4: docx | D4: 3.45 | E4: 0B10FED99D7889F89A158E1057ED5C9719F7975626BE297DFD2F774532E70421 | F4: Yes | G4: valid | H4: 75.37s
A5: 3 | B5: 00034888.jpg | C5: jpg | D5: 1.55 | E5: 1C18181DACE38380DBC7F68F9AD13C5AE5E07A3BC5669BBEB9913FDDC3565986 | F5: No | G5: false positive | H5: 75.37s | J5: SUMMARY
A6: 4 | B6: 00089370.jpg | C6: jpg | D6: 1.74 | E6: A7F9A4D0B6E852F01D564A03FBF38A273FF082EBEA54D7919FC0E20525C97D7C | F6: No | G6: false positive | H6: 75.37s | J6: Total Recovered Files (Ret) | K6: =COUNTIF(B:B,"<>") -> 28
A7: 5 | B7: 00092932.jpg | C7: jpg | D7: 0.74 | E7: 93EE0ADE57664017AC7ABA5C5DF1205C42029CB0AB26C8D5E8DAFE69CBAFF453 | F7: No | G7: false positive | H7: 75.37s | J7: Valid Files (RnR) | K7: =COUNTIF(F:F,"Yes") -> 9
A8: 6 | B8: 00097761.jpg | C8: jpg | D8: 1.42 | E8: F466BB7C6D307E133DF49BD8DADB9B9FAD0D4ACCCF19B1240297540D9EC20AA6 | F8: No | G8: false positive | H8: 75.37s | J8: Corrupted Files | K8: =COUNTIF(G:G,"Corrupted") -> 0
A9: 7 | B9: 00101085.jpg | C9: jpg | D9: 0.05 | E9: 2165040DF007CEED04AC9B01274410CAE8D13F94E0FC8B62AD1615AA45486F04 | F9: No | G9: false positive | H9: 75.37s | J9: False Positives | K9: =COUNTIF(G:G,"False Positive") -> 18
A10: 8 | B10: 00101194.jpg | C10: jpg | D10: 0.18 | E10: 9FA94258982246127F10AA20A4D074FCA6A5E35C5DFB9229C05E73BCC315C248 | F10: No | G10: false positive | H10: 75.37s | J10: Processing Time (sec) | K10: =H3 -> 75.37s
A11: 9 | B11: 00101571.jpg | C11: jpg | D11: 0.18 | E11: 9FA94258982246127F10AA20A4D074FCA6A5E35C5DFB9229C05E73BCC315C248 | F11: No | G11: false positive | H11: 75.37s
A12: 10 | B12: 00101948.jpg | C12: jpg | D12: 0.57 | E12: B29E13019F3FF8F3512289B5502F4401B4A262814F312D96610E983D7164BAB7 | F12: No | G12: false positive | H12: 75.37s
A13: 11 | B13: 00103121.jpg | C13: jpg | D13: 0.45 | E13: 83DC1D3863AB6C3440F75776D487CB7BE024C7025B0076FFA8257BB320228207 | F13: No | G13: false positive | H13: 75.37s
A14: 12 | B14: 00104048.jpg | C14: jpg | D14: 0.31 | E14: 5EAF3D171232F1795830FE413BD718FCF513A3F82621694A164505CF0EEAA5F6 | F14: No | G14: false positive | H14: 75.37s
A15: 13 | B15: 00104685.jpg | C15: jpg | D15: 0.27 | E15: B8D4F2976C7E427242F3635C12D1291832326402019A2BFC9430D23B7CB93839 | F15: No | G15: false positive | H15: 75.37s
A16: 14 | B16: 00105230.jpg | C16: jpg | D16: 0.16 | E16: FF724CB8D7337C3814DCA9BE4B33B9BCF1FD9649DB55D15F52909BDAB6AE9CF0 | F16: No | G16: false positive | H16: 75.37s
A17: 15 | B17: 00105563.jpg | C17: jpg | D17: 0.23 | E17: 05FCCB3A07DD20CAF15FE143DBF28EAF7128CC9F9CC841E6E82B156F2FDBE1FD | F17: No | G17: false positive | H17: 75.37s
A18: 16 | B18: 00106044.jpg | C18: jpg | D18: 0.17 | E18: DA6C96566B6636039EBB4CEBC772F5C1D0D90A6EFB36592E18079EC14D0B655E | F18: No | G18: false positive | H18: 75.37s
A19: 17 | B19: 00106399.jpg | C19: jpg | D19: 0.17 | E19: 380982D0AF8A0D174F2136C9B6B9B8ABEE71AAFF2A140D23FFBBAE81A158BB4E | F19: No | G19: false positive | H19: 75.37s
A20: 18 | B20: 00106741.jpg | C20: jpg | D20: 0.11 | E20: E8C344D9FB8663B17F236B22796020996AD60D7DA00DDB3E484C2003F77756F5 | F20: No | G20: false positive | H20: 75.37s
A21: 19 | B21: 00106960.jpg | C21: jpg | D21: 0.37 | E21: 9A76A6E3D8BB880232A7C5953763669870CDA98C8D97402C8BB8F3B742682BE2 | F21: No | G21: false positive | H21: 75.37s
A22: 20 | B22: 00787312.mp4 | C22: mp4 | D22: 46.66 | E22: 64ACC63D9C97C722D94EFCD7FC88CABB0C50FDC4D5C1078B1294EE9717D389EF | F22: Yes | G22: valid | H22: 75.37s
... A29: 27 | B29: 00178584.png | C29: png | D29: 2.83 | E29: 9A6A4C465D10968F5DAF41E3F80CC0B08E1D0B8ADC1ED4654D560AAE87FB4886 | F29: Yes | G29: valid | H29: 75.37s

Sheet 3 - Foremost S2
A1: Foremost - Scenario 2 - Fragmented Deletion
A2: # | B2: Recovered File Name | C2: File Type | D2: Size (MB) | E2: SHA-256 Hash | F2: Match? (Yes/No) | G2: Status | H2: Processing Time (sec)
A3: 1 | B3: 00627574.zip | C3: zip | D3: 35.81 | E3: 202FBDCBB867CBBC65F86C26468129D0B987BFDB58346D41FE94E5D60EFB3216 | F3: No | G3: False Positive | H3: 967.83s
A4: 2 | B4: 06454321.bmp | C4: bmp | D4: 0 | E4: 3DD58427A37E0718F6DD66E0594679C4ED58EE37A77063308DD73E247141E068 | F4: No | G4: False Positive | H4: 967.83s
A5: 3 | B5: 06306088.dll | C5: dll | D5: 0.19 | E5: F158910754927A5499486482C1C78881D645A01BC1DB521647361426A97E8725 | F5: No | G5: False Positive | H5: 967.83s
A6: 4 | B6: 06306504.dll | C6: dll | D6: 0.75 | E6: 9DACE616D9B06CB00C242C40A0414684C70EC1BC6072A02ADA5EF1CB3ED00B1A | F6: No | G6: False Positive | H6: 967.83s | J6: SUMMARY
A7: 5 | B7: 06312424.dll | C7: dll | D7: 0.08 | E7: 9A18851994C4193574AF03CFEF8EAF5C1DEBE97DA2F1E7CE0AE0B60CEFDA0F70 | F7: No | G7: False Positive | H7: 967.83s | J7: Total Recovered Files (Ret) | K7: =COUNTIF(B:B,"<>") -> 478
A8: 6 | B8: 06312616.dll | C8: dll | D8: 2.27 | E8: 5A0221BD857462230445EB060D16147834287559E887EE09A9E1E9B5D892099C | F8: No | G8: False Positive | H8: 967.83s | J8: Valid Files (RnR) | K8: =COUNTIF(F:F,"Yes") -> 20
A9: 7 | B9: 06318216.dll | C9: dll | D9: 0.12 | E9: 83F08F8A35C084B244C9E40488F67215CA0F1DA2322F8837463B8AFE94077308 | F9: No | G9: False Positive | H9: 967.83s | J9: Corrupted Files | K9: =COUNTIF(G:G,"Corrupted") -> 0
A10: 8 | B10: 06318488.dll | C10: dll | D10: 0 | E10: 7BB5F372F756D02EE310BA0205B158D6BAB93F562D02EDC514FFD489CFFEA335 | F10: No | G10: False Positive | H10: 967.83s | J10: False Positives | K10: =COUNTIF(G:G,"False Positive") -> 457
A11: 9 | B11: 06318512.dll | C11: dll | D11: 0.41 | E11: DF9748999B401FBF65197C1B5EE4831B3B13F51DCAF4DF557A5956A17D738145 | F11: No | G11: False Positive | H11: 967.83s | J11: Processing Time (sec) | K11: =H3 -> 967.83s
A12: 10 | B12: 06319368.dll | C12: dll | D12: 2.76 | E12: F161BC5DDA943981F79A4511B300F891E753DF07FBB3BC402C1A50FC262DBF57 | F12: No | G12: False Positive | H12: 967.83s
A13: 11 | B13: 06330408.dll | C13: dll | D13: 0.66 | E13: C942F3434A2CD779BF79976D735DAD6D7C42B18F7CA79B0C26AF70FDAABB94C8 | F13: No | G13: False Positive | H13: 967.83s
A14: 12 | B14: 06331776.dll | C14: dll | D14: 0.02 | E14: E47A137BC8EEC6941830E28BE826674CFE4D08412AEDFDC096C01CE5358940B8 | F14: No | G14: False Positive | H14: 967.83s
A15: 13 | B15: 06331840.dll | C15: dll | D15: 0.04 | E15: 8A6D6187CF6DE62AAC9347195E8C735EDFA3A9106A9AB83EDBB937B1C0D08046 | F15: No | G15: False Positive | H15: 967.83s
A16: 14 | B16: 06331944.dll | C16: dll | D16: 0.38 | E16: 5D8F6882C5627416899BEF3250932C026CC2233292ED483EFBC30C4131EA6684 | F16: No | G16: False Positive | H16: 967.83s
A17: 15 | B17: 06344200.dll | C17: dll | D17: 0.01 | E17: 4BFF7515177204E32E61B63D2321DA0854233F30B5D8781FE583768181CEEBC2 | F17: No | G17: False Positive | H17: 967.83s
A18: 16 | B18: 06344256.dll | C18: dll | D18: 0.03 | E18: 2E524ABC9C488C56843AFBDA27245D5AEE41AFA5FEBF292C859751E46BE4C1E6 | F18: No | G18: False Positive | H18: 967.83s
A19: 17 | B19: 06344336.dll | C19: dll | D19: 0.04 | E19: B8B504005EFD8CDB18104DE01BA30BA268B19EEDE8C4255151D1876F2911EFC8 | F19: No | G19: False Positive | H19: 967.83s
A20: 18 | B20: 06344432.dll | C20: dll | D20: 0.14 | E20: 0B4B82FB0B06CAA7DFB2B4096952E20117AB0EF7CC5AA1B40D3FBABE2BB81FEC | F20: No | G20: False Positive | H20: 967.83s
A21: 19 | B21: 06344752.dll | C21: dll | D21: 0.79 | E21: 1AB9B186E1E8D008DE756C4095416B89F98B50D3BDEA68F442D464F7BD82EEC4 | F21: No | G21: False Positive | H21: 967.83s
A22: 20 | B22: 06346424.dll | C22: dll | D22: 1.16 | E22: 070E6C39ED0BBD057BF2B3F16B1EEA5B14EEB0D04A6069F847CF8E3A1475181F | F22: No | G22: False Positive | H22: 967.83s
A23: 21 | B23: 06413432.dll | C23: dll | D23: 0.07 | E23: 4861CE603A58134F6F0A49C6B16F95C97FE108C303CC097B70FB15060F1C1D37 | F23: No | G23: False Positive | H23: 967.83s
... A479: 477 | B479: 15353346.png | C479: png | D479: 0 | E479: F50424E438E1656DB36A0D8CB03200410A0A899A8091FA00F6BB338FD69FD9E3 | F479: No | G479: False Positive | H479: 967.83s

Sheet 4 - PhotoRec S1
A1: PhotoRec - Scenario 1 - Normal Deletion
A2: # | B2: Recovered File Name | C2: File Type | D2: Size (KB/MB) | E2: SHA-256 Hash | F2: Match? (Yes/No) | G2: Status | H2: Processing Time (sec)
A3: 1 | B3: f9731672.bmp | C3: bmp | D3: 2.25 | E3: BAC5792B0A92C84A07AF53231D19090C827B63A0A5050FE5AC300A13E76D5EF8 | F3: No | G3: False Positive | H3: 957.01s
A4: 2 | B4: f9628432.cab | C4: cab | D4: 0.01 | E4: A7012885B9D0353A791216229BB8093CC431309E3D19DDA913C96DCEBA756E0C | F4: No | G4: False Positive | H4: 957.01s
A5: 3 | B5: f9628480.cab | C5: cab | D5: 0.24 | E5: DEFBE7E298D962CC264005CD36630213B228A4893E38066256B9F2BB22E96344 | F5: No | G5: False Positive | H5: 957.01s
A6: 4 | B6: f9629008.cab | C6: cab | D6: 0.09 | E6: CE3BDE76AA735628E5858DADCB724D8DB321DE273544F64F66B0F64408A2F37D | F6: No | G6: False Positive | H6: 957.01s
A7: 5 | B7: f9629216.cab | C7: cab | D7: 37.3 | E7: FDFE0CEDA2CD28629B372087F4A96DA1F9B26A6F6156BE9F01D08FEBB567A672 | F7: No | G7: False Positive | H7: 957.01s
A8: 6 | B8: f9711824.cab | C8: cab | D8: 0.04 | E8: B0FDDBEA9FDC2520C561E8B22484F27532A255FEC156234D9679C3BDEDDEE2FE | F8: No | G8: False Positive | H8: 957.01s
A9: 7 | B9: f10348264.dll | C9: dll | D9: 0.72 | E9: AA5D32591A441D2791022DC7FBA5E359F73D7ABD2A3A2E0C25E169ABC1E51659 | F9: No | G9: False Positive | H9: 957.01s
A10: 8 | B10: f10349752.dll | C10: dll | D10: 0.31 | E10: B2BC6E5A27CBD53E6E719312B056B74E1796EE4E772848491149819FBF92E72F | F10: No | G10: False Positive | H10: 957.01s
A11: 9 | B11: f10350400.dll | C11: dll | D11: 0.08 | E11: C2ECD0636BD424DB5426A0C2A986364F8C30BCE816366F87ABCDCF7A16943A98 | F11: No | G11: False Positive | H11: 957.01s
A12: 10 | B12: f10350576.dll | C12: dll | D12: 0.18 | E12: 694D3D2F2F5A3CA2043014BF113C6455C939F0E33A1AB5CC4C24D6A38493336A | F12: No | G12: False Positive | H12: 957.01s
A13: 11 | B13: f10350960.dll | C13: dll | D13: 0.11 | E13: 50BCB7515CF773362B268A6691C36F07090A8FDE3572641F3FA31875E2CE7F45 | F13: No | G13: False Positive | H13: 957.01s
A14: 12 | B14: f10351208.dll | C14: dll | D14: 0.73 | E14: 419DEE14FB795F9516E9375931098F319C6BA68068C98C695A458019E178DC07 | F14: No | G14: False Positive | H14: 957.01s
A15: 13 | B15: f10355232.dll | C15: dll | D15: 0.61 | E15: 56EF01802968868CF096E6EB4F3C0C043F0D5F399C51FA8D1948DB1E4233C245 | F15: No | G15: False Positive | H15: 957.01s
A16: 14 | B16: f10356504.dll | C16: dll | D16: 0.14 | E16: 8FECFEFDDDE96E2D7A99B0F752391C97346BA30515E37E28E3A2635FC9336623 | F16: No | G16: False Positive | H16: 957.01s | J16: SUMMARY
A17: 15 | B17: f10357992.dll | C17: dll | D17: 0.01 | E17: 295C8A1BF013B83DF9A25A562B9A09428BD2C932EA5979EC3CF7017405E66FB8 | F17: No | G17: False Positive | H17: 957.01s | J17: Total Recovered Files (Ret) | K17: =COUNTA(B:B,"<>") -> 992
A18: 16 | B18: f10359144.dll | C18: dll | D18: 0.01 | E18: A3C97EF0FAF8000697C98A9FAA25A6A3CD0E20B5F8522821409A81A7FE4E8899 | F18: No | G18: False Positive | H18: 957.01s | J18: Valid Files (RnR) | K18: =COUNTIF(F:F,"Yes") -> 23
A19: 17 | B19: f10359184.dll | C19: dll | D19: 0.15 | E19: 3F164E2A4DD294EF49CF7C038C346E62FA287AD32295630A90DF1A12A62C22AE | F19: No | G19: False Positive | H19: 957.01s | J19: Corrupted Files | K19: =COUNTIF(G:G,"Corrupted") -> 1
A20: 18 | B20: f10359512.dll | C20: dll | D20: 0.29 | E20: D595F428E8825689DF75C9F0F0432B1253B07158123B885C2CFB91A680FD9EDB | F20: No | G20: False Positive | H20: 957.01s | J20: False Positives | K20: =COUNTIF(G:G,"False Positive") -> 964
A21: 19 | B21: f6304040.dll | C21: dll | D21: 0.19 | E21: F158910754927A5499486482C1C78881D645A01BC1DB521647361426A97E8725 | F21: No | G21: False Positive | H21: 957.01s | J21: Processing Time (sec) | K21: =H3 -> 957.01s
A22: 20 | B22: f6304456.dll | C22: dll | D22: 0.75 | E22: 9DACE616D9B06CB00C242C40A0414684C70EC1BC6072A02ADA5EF1CB3ED00B1A | F22: No | G22: False Positive | H22: 957.01s
A23: 21 | B23: f6310376.dll | C23: dll | D23: 0.08 | E23: 9A18851994C4193574AF03CFEF8EAF5C1DEBE97DA2F1E7CE0AE0B60CEFDA0F70 | F23: No | G23: False Positive | H23: 957.01s
A24: 22 | B24: f6310568.dll | C24: dll | D24: 2.27 | E24: 5A0221BD857462230445EB060D16147834287559E887EE09A9E1E9B5D892099C | F24: No | G24: False Positive | H24: 957.01s
A25: 23 | B25: f6316168.dll | C25: dll | D25: 0.12 | E25: 83F08F8A35C084B244C9E40488F67215CA0F1DA2322F8837463B8AFE94077308 | F25: No | G25: False Positive | H25: 957.01s
A26: 24 | B26: f6316440.dll | C26: dll | D26: 0 | E26: 7BB5F372F756D02EE310BA0205B158D6BAB93F562D02EDC514FFD489CFFEA335 | F26: No | G26: False Positive | H26: 957.01s
A27: 25 | B27: f6316464.dll | C27: dll | D27: 0.41 | E27: DF9748999B401FBF65197C1B5EE4831B3B13F51DCAF4DF557A5956A17D738145 | F27: No | G27: False Positive | H27: 957.01s
A28: 26 | B28: f6317320.dll | C28: dll | D28: 2.76 | E28: 6CB2F9DEAD570ACA6D4831A2234DACF260B9528D9A0FA6D887781ADA5B9C688F | F28: No | G28: False Positive | H28: 957.01s
A29: 27 | B29: f6328360.dll | C29: dll | D29: 0.66 | E29: C942F3434A2CD779BF79976D735DAD6D7C42B18F7CA79B0C26AF70FDAABB94C8 | F29: No | G29: False Positive | H29: 957.01s
A30: 28 | B30: f6329728.dll | C30: dll | D30: 0.02 | E30: E47A137BC8EEC6941830E28BE826674CFE4D08412AEDFDC096C01CE5358940B8 | F30: No | G30: False Positive | H30: 957.01s
A31: 29 | B31: f6329792.dll | C31: dll | D31: 0.04 | E31: 8A6D6187CF6DE62AAC9347195E8C735EDFA3A9106A9AB83EDBB937B1C0D08046 | F31: No | G31: False Positive | H31: 957.01s
A32: 30 | B32: f6329896.dll | C32: dll | D32: 0.38 | E32: 5D8F6882C5627416899BEF3250932C026CC2233292ED483EFBC30C4131EA6684 | F32: No | G32: False Positive | H32: 957.01s
A33: 31 | B33: f6330696.dll | C33: dll | D33: 5.59 | E33: 2ED7073E279D968A2C01FD45DEDCC4C2843398AB4B7B410A396C42855686A10C | F33: No | G33: False Positive | H33: 957.01s
... A364: 362 | B364: t1923848.jpg | C364: jpg | D364: 0.01 | E364: 2DB3BEFC5C1A1E295F059F06BABC8A31578FF32606C89948534109AEF8B79A3A | F364: No | G364: Corrupted | H364: 957.01s
A365: 363 | B365: f0785264_ftyp.mov | C365: mov | D365: 0 | E365: 022929A0F9F3D2879CA6B39A3D1E58A69455788405937D2C8FB4B520E37C532F | F365: No | H365: 957.01s
A366: 364 | B366: f0880816_ftyp.mov | C366: mov | D366: 66.46 | E366: 523F174067C78AB766A75CAC1E7D3E20E04606D1F81E829364BEE43B75A82051 | F366: yes | G366: valid | H366: 957.01s
A367: 365 | B367: f1016928_ftyp.mov | C367: mov | D367: 56.63 | E367: 5EEA82D87304F3DB8F421F927461B5CE421AF4D494E59E3C274134E9106E5631 | F367: yes | G367: valid | H367: 957.01s
A368: 366 | B368: f1132904_ftyp.mov | C368: mov | D368: 0 | E368: D0902BDAFFEC49BCC74A5A8D308DB4C96843EC59955FA07ECDCE5E035FD97254 | F368: No | H368: 957.01s
A369: 367 | B369: f1269736_ftyp.mov | C369: mov | D369: 68.52 | E369: AE0B6D5AE2D87D11D346D775F29596C4F55D984851D2CC9CC6FF5B9BA1C8D569 | F369: yes | G369: valid | H369: 957.01s
A370: 368 | B370: f1410072_ftyp.mov | C370: mov | D370: 250.87 | E370: 7AC0052C9B679BA18426C39EE60988D1E376D423C79DDECB3A1EE87EB84F7217 | F370: yes | G370: valid | H370: 957.01s
...

Sheet 5 - PhotoRec S2
A1: PhotoRec - Scenario 2 - Fragmented Deletion
A2: # | B2: Recovered File Name | C2: File Type | D2: Size (KB/MB) | E2: SHA-256 Hash | F2: Match? (Yes/No) | G2: Status | H2: Processing Time (sec)
A3: 1 | B3: f9731672.bmp | C3: bmp | D3: 2.25 | E3: BAC5792B0A92C84A07AF53231D19090C827B63A0A5050FE5AC300A13E76D5EF8 | F3: No | G3: False Positive | H3: 2000.06s
A4: 2 | B4: f9628432.cab | C4: cab | D4: 0.01 | E4: A7012885B9D0353A791216229BB8093CC431309E3D19DDA913C96DCEBA756E0C | F4: No | G4: False Positive | H4: 2000.06s
A5: 3 | B5: f9628480.cab | C5: cab | D5: 0.24 | E5: DEFBE7E298D962CC264005CD36630213B228A4893E38066256B9F2BB22E96344 | F5: No | G5: False Positive | H5: 2000.06s
A6: 4 | B6: f9629008.cab | C6: cab | D6: 0.09 | E6: CE3BDE76AA735628E5858DADCB724D8DB321DE273544F64F66B0F64408A2F37D | F6: No | G6: False Positive | H6: 2000.06s | J6: SUMMARY
A7: 5 | B7: f9629216.cab | C7: cab | D7: 37.3 | E7: FDFE0CEDA2CD28629B372087F4A96DA1F9B26A6F6156BE9F01D08FEBB567A672 | F7: No | G7: False Positive | H7: 2000.06s | J7: Total Recovered Files (Ret) | K7: =COUNTA(B:B) -> 962
A8: 6 | B8: f9711824.cab | C8: cab | D8: 0.04 | E8: B0FDDBEA9FDC2520C561E8B22484F27532A255FEC156234D9679C3BDEDDEE2FE | F8: No | G8: False Positive | H8: 2000.06s | J8: Valid Files (RnR) | K8: =COUNTIF(F:F,"Yes") -> 20
A9: 7 | B9: f10340216.dll | C9: dll | D9: 3.63 | E9: 9C316E6E31D1E4F9BE8A01509E5C4CB17AA9ADA72C7FCD224BA29D2A2BE93E70 | F9: No | G9: False Positive | H9: 2000.06s | J9: Corrupted Files | K9: =COUNTIF(G:G,"Corrupted") -> 1
A10: 8 | B10: f10348264.dll | C10: dll | D10: 0.72 | E10: AA5D32591A441D2791022DC7FBA5E359F73D7ABD2A3A2E0C25E169ABC1E51659 | F10: No | G10: False Positive | H10: 2000.06s | J10: False Positives | K10: =COUNTIF(G:G,"False Positive") -> 937
A11: 9 | B11: f10349752.dll | C11: dll | D11: 0.31 | E11: B2BC6E5A27CBD53E6E719312B056B74E1796EE4E772848491149819FBF92E72F | F11: No | G11: False Positive | H11: 2000.06s | J11: Processing Time (sec) | K11: =H3 -> 2000.06s
A12: 10 | B12: f10350400.dll | C12: dll | D12: 0.08 | E12: C2ECD0636BD424DB5426A0C2A986364F8C30BCE816366F87ABCDCF7A16943A98 | F12: No | G12: False Positive | H12: 2000.06s
A13: 11 | B13: f10350576.dll | C13: dll | D13: 0.18 | E13: 694D3D2F2F5A3CA2043014BF113C6455C939F0E33A1AB5CC4C24D6A38493336A | F13: No | G13: False Positive | H13: 2000.06s
A14: 12 | B14: f10350960.dll | C14: dll | D14: 0.11 | E14: 50BCB7515CF773362B268A6691C36F07090A8FDE3572641F3FA31875E2CE7F45 | F14: No | G14: False Positive | H14: 2000.06s
A15: 13 | B15: f10351208.dll | C15: dll | D15: 0.73 | E15: 419DEE14FB795F9516E9375931098F319C6BA68068C98C695A458019E178DC07 | F15: No | G15: False Positive | H15: 2000.06s
A16: 14 | B16: f10355232.dll | C16: dll | D16: 0.61 | E16: 56EF01802968868CF096E6EB4F3C0C043F0D5F399C51FA8D1948DB1E4233C245 | F16: No | G16: False Positive | H16: 2000.06s
A17: 15 | B17: f10356504.dll | C17: dll | D17: 0.14 | E17: 8FECFEFDDDE96E2D7A99B0F752391C97346BA30515E37E28E3A2635FC9336623 | F17: No | G17: False Positive | H17: 2000.06s
A18: 16 | B18: f10357992.dll | C18: dll | D18: 0.01 | E18: 295C8A1BF013B83DF9A25A562B9A09428BD2C932EA5979EC3CF7017405E66FB8 | F18: No | G18: False Positive | H18: 2000.06s
A19: 17 | B19: f10359144.dll | C19: dll | D19: 0.01 | E19: A3C97EF0FAF8000697C98A9FAA25A6A3CD0E20B5F8522821409A81A7FE4E8899 | F19: No | G19: False Positive | H19: 2000.06s
A20: 18 | B20: f10359184.dll | C20: dll | D20: 0.15 | E20: 3F164E2A4DD294EF49CF7C038C346E62FA287AD32295630A90DF1A12A62C22AE | F20: No | G20: False Positive | H20: 2000.06s
A21: 19 | B21: f10359512.dll | C21: dll | D21: 0.29 | E21: D595F428E8825689DF75C9F0F0432B1253B07158123B885C2CFB91A680FD9EDB | F21: No | G21: False Positive | H21: 2000.06s
A22: 20 | B22: f6304040.dll | C22: dll | D22: 0.19 | E22: F158910754927A5499486482C1C78881D645A01BC1DB521647361426A97E8725 | F22: No | G22: False Positive | H22: 2000.06s
A23: 21 | B23: f6304456.dll | C23: dll | D23: 0.75 | E23: 9DACE616D9B06CB00C242C40A0414684C70EC1BC6072A02ADA5EF1CB3ED00B1A | F23: No | G23: False Positive | H23: 2000.06s
... A339: 337 | B339: f9705616.java | C339: java | D339: 0 | E339: CC5C41D02F5D05324FD67D5321FAD6FE5C21E87F53DAAD632537B6EE58205DDD | F339: No | G339: False Positive | H339: 2000.06s
A340: 338 | B340: f2007320.jp2 | C340: jp2 | D340: 28.35 | E340: 9A3F6E69493D0577DBFBF279A55F77504E16C8ED9FB4D7B1EBADE6FA78705B83 | F340: No | H340: 2000.06s
A341: 339 | B341: f0420480.jpg | C341: jpg | D341: 0.31 | E341: 5EAF3D171232F1795830FE413BD718FCF513A3F82621694A164505CF0EEAA5F6 | F341: No | G341: False Positive | H341: 2000.06s
A342: 340 | B342: f0698872.jpg | C342: jpg | D342: 6.18 | E342: 45DD659209929665EBDF6D670130A18E7818DAF12E2FDB844D1C613DDA11A2C8 | F342: Yes | G342: Valid | H342: 2000.06s
A343: 341 | B343: f0711536.jpg | C343: jpg | D343: 4.53 | E343: D39E9D800BD621BDC27564FC82D09E6AF602696688F7607A62C1EE7877730C73 | F343: Yes | G343: Valid | H343: 2000.06s
A344: 342 | B344: f0720816.jpg | C344: jpg | D344: 3.61 | E344: 8573F63BF67538BA97AFB254849071125E2E0C8397BAE75CE7AECBBF43C6FA85 | F344: Yes | G344: Valid | H344: 2000.06s
A345: 343 | B345: f0728216.jpg | C345: jpg | D345: 2.81 | E345: 6B3B678CB4C25E0991C5047D732C158F3D0989F9B2137BF40D49F285E6CACCD6 | F345: Yes | G345: Valid | H345: 2000.06s
A346: 344 | B346: f0733968.jpg | C346: jpg | D346: 7.45 | E346: 760C4B1A4A22602D762DF6FCEA43EF972E87D2E5E3D8F3F3A095BC47B3AD261F | F346: Yes | G346: Valid | H346: 2000.06s
A347: 345 | B347: f0749224.jpg | C347: jpg | D347: 2.4 | E347: 82EA6696F670C009AF187D0670A3752E5C6FF266F4EBBED7C58D446E66EAF847 | F347: Yes | G347: Valid | H347: 2000.06s
A348: 346 | B348: t0749224.jpg | C348: jpg | D348: 0.01 | E348: 2DB3BEFC5C1A1E295F059F06BABC8A31578FF32606C89948534109AEF8B79A3A | F348: No | G348: Corrupted | H348: 2000.06s
A349: 347 | B349: f0754152_ftyp.mov | C349: mov | D349: 250.87 | E349: 7AC0052C9B679BA18426C39EE60988D1E376D423C79DDECB3A1EE87EB84F7217 | F349: Yes | G349: Valid | H349: 2000.06s
A350: 348 | B350: f1267928_ftyp.mov | C350: mov | D350: 68.52 | E350: AE0B6D5AE2D87D11D346D775F29596C4F55D984851D2CC9CC6FF5B9BA1C8D569 | F350: Yes | G350: Valid | H350: 2000.06s
A351: 349 | B351: f1408264_ftyp.mov | C351: mov | D351: 0 | E351: D0902BDAFFEC49BCC74A5A8D308DB4C96843EC59955FA07ECDCE5E035FD97254 | F351: No | H351: 2000.06s
A352: 350 | B352: f1545096_ftyp.mov | C352: mov | D352: 56.63 | E352: 5EEA82D87304F3DB8F421F927461B5CE421AF4D494E59E3C274134E9106E5631 | F352: Yes | G352: Valid | H352: 2000.06s
A353: 351 | B353: f1661072_ftyp.mov | C353: mov | D353: 66.46 | E353: 523F174067C78AB766A75CAC1E7D3E20E04606D1F81E829364BEE43B75A82051 | F353: Yes | G353: Valid | H353: 2000.06s
A354: 352 | B354: f1797184_ftyp.mov | C354: mov | D354: 0 | E354: 022929A0F9F3D2879CA6B39A3D1E58A69455788405937D2C8FB4B520E37C532F | F354: No | H354: 2000.06s
A355: 353 | B355: f1892736_Image_Heavy_PDF_A4_Size.pdf | C355: pdf | D355: 7.97 | E355: 89D41043D0F7A411545A67C18A7CAEAE472DBB307561564704603747730F8CBF | F355: Yes | G355: Valid | H355: 2000.06s
...

Sheet 6 - Scalpel S1
A1: Scalpel - Scenario 1 - Normal Deletion
A2: # | B2: Recovered File Name | C2: File Type | D2: Size (KB/MB) | E2: SHA-256 Hash | F2: Match? (Yes/No) | G2: Status | H2: Processing Time (sec)
A3: 1 | B3: 00000874.doc | C3: doc | D3: 0.52 | E3: 8E73DE0D4484BC02750B3B4FF3A3B86490E829CCF4FA05FA8765DB1AA17F1221 | F3: No | G3: False Positive | H3: 892.48s
A4: 2 | B4: 00000875.doc | C4: doc | D4: 9.54 | E4: CF45AE40D01455B45F0B67A31573DABD27DB99B50D89A8BF8995CE0B9AAA2CF6 | F4: No | G4: False Positive | H4: 892.48s
A5: 3 | B5: 00000876.doc | C5: doc | D5: 9.54 | E5: D2CCC76818245A8EEFB1B444C380A3CB06FA957AF8A06D0104D971667B572443 | F5: No | G5: False Positive | H5: 892.48s
A6: 4 | B6: 00000877.doc | C6: doc | D6: 9.54 | E6: 65DCBE680E9C90AA1FB7C5CC00ED0BFA9313D5744C85D5FAD92BDA4D62BA63EF | F6: No | G6: False Positive | H6: 892.48s
A7: 5 | B7: 00000878.doc | C7: doc | D7: 9.54 | E7: CF45AE40D01455B45F0B67A31573DABD27DB99B50D89A8BF8995CE0B9AAA2CF6 | F7: No | G7: False Positive | H7: 892.48s
A8: 6 | B8: 00000874.doc | C8: doc | D8: 13.148 | E8: 8E73DE0D4484BC02750B3B4FF3A3B86490E829CCF4FA05FA8765DB1AA17F1222 | F8: No | G8: False Positive | H8: 892.48s
A9: 7 | B9: 00000000.jpg | C9: jpg | D9: 2.4 | E9: 6E69945852619843997130CAE262777F43348CF8F497DB2609923CBA8FC7D8A9 | F9: No | G9: Corrupted | H9: 892.48s
A10: 8 | B10: 00000001.jpg | C10: jpg | D10: 4.79 | E10: DE5DAC6E5DE9D047FEEA79BCEE3707594ABB0AA894109FE0309DFB81C6711094 | F10: No | G10: False Positive | H10: 892.48s
A11: 9 | B11: 00000002.jpg | C11: jpg | D11: 4.07 | E11: 58896FD1F4F4918FAD18E2A1B0AA618565586E3D206303BE341C8DE12FE139A5 | F11: No | G11: False Positive | H11: 892.48s
A12: 10 | B12: 00000003.jpg | C12: jpg | D12: 4.98 | E12: BDDFC6931358122784EA575FD3DC630540EA4A4E8E1CBC5A8F5A74CA0069F233 | F12: No | G12: False Positive | H12: 892.48s
A13: 11 | B13: 00000004.jpg | C13: jpg | D13: 4.98 | E13: DB8AA84B37F7F91C6E883C6ABACA410250E04A3F8F582BEDE933BA0EEF082D1A | F13: No | G13: False Positive | H13: 892.48s
A14: 12 | B14: 00000005.jpg | C14: jpg | D14: 4.97 | E14: 22768BD0B20243458580A2AE1ABD19497A0CD362A65590752672EBD52A841681 | F14: No | G14: False Positive | H14: 892.48s
... A18: 16 | B18: 00000009.jpg | C18: jpg | D18: 4.99 | E18: 5C9473808C387A4EFF6CA3DDFCB9458026C2614637A02E7D3F3A758BDC993EC1 | F18: No | G18: False Positive | H18: 892.48s
A19: 17 | B19: 00000010.jpg | C19: jpg | D19: 4.98 | E19: 08408CEBDD17B8675DD1544759EF980525BC6108C836374BB4C53FD4C3014724 | F19: No | G19: False Positive | H19: 892.48s | J19: SUMMARY
A20: 18 | B20: 00000011.jpg | C20: jpg | D20: 4.92 | E20: 3DE4CA5A305BB7C4C050AFCC582F8F6AF094ACDF8CBAA00192E1570E68999EE4 | F20: No | G20: False Positive | H20: 892.48s | J20: Total Recovered Files (Ret) | K20: =COUNTA(B:B,"<>") -> 882
A21: 19 | B21: 00000012.jpg | C21: jpg | D21: 4.99 | E21: 6841E57977E275A80A535A7C4783091C9629A7C323F5A81AB1F7CE1DBB344083 | F21: No | G21: False Positive | H21: 892.48s | J21: Valid Files (RnR) | K21: =COUNTIF(F:F,"Yes") -> 3
A22: 20 | B22: 00000013.jpg | C22: jpg | D22: 4.84 | E22: 069D1934F80BCC611F07B56D2AA1234BED5360AD849CDE6304C5BE030AEC5880 | F22: No | G22: False Positive | H22: 892.48s | J22: Corrupted Files | K22: =COUNTIF(G:G,"Corrupted") -> 2
A23: 21 | B23: 00000014.jpg | C23: jpg | D23: 4.9 | E23: 394CD6ACADA5D2064B2F5F3D7E96E7FACF8D62EB3FE6BBA464D092EEAA60517B | F23: No | G23: False Positive | H23: 892.48s | J23: False Positives | K23: =COUNTIF(G:G,"False Positive") -> 875
A24: 22 | B24: 00000015.jpg | C24: jpg | D24: 4.94 | E24: 677E7AB32AC4335D7AB05C784B2C60532650D78B3E63402B19F294BBDB907DDD | F24: No | G24: False Positive | H24: 892.48s | J24: Processing Time (sec) | K24: =H4 -> 892.48s
A25: 23 | B25: 00000016.jpg | C25: jpg | D25: 4.77 | E25: E385DEBC93FB287DA43758FEE95A64F4C9647A163AE245E5A8A9A74FCC5CFC1A | F25: No | G25: False Positive | H25: 892.48s
A26: 24 | B26: 00000017.jpg | C26: jpg | D26: 4.93 | E26: B7F142363325A88B0AF8070D46578F22D1C7C588077D317F300E42EC2A946F3F | F26: No | G26: False Positive | H26: 892.48s
A27: 25 | B27: 00000018.jpg | C27: jpg | D27: 4.82 | E27: 139B2C93577D0A4B1DE13A3D6474C22E618A843A5A6F8D568E447BBCA9069206 | F27: No | G27: False Positive | H27: 892.48s
A28: 26 | B28: 00000019.jpg | C28: jpg | D28: 2.81 | E28: 6B3B678CB4C25E0991C5047D732C158F3D0989F9B2137BF40D49F285E6CACCD6 | F28: Yes | G28: Valid | H28: 892.48s
A29: 27 | B29: 00000020.jpg | C29: jpg | D29: 3.61 | E29: 8573F63BF67538BA97AFB254849071125E2E0C8397BAE75CE7AECBBF43C6FA85 | F29: Yes | G29: Valid | H29: 892.48s
A30: 28 | B30: 00000021.jpg | C30: jpg | D30: 4.53 | E30: D39E9D800BD621BDC27564FC82D09E6AF602696688F7607A62C1EE7877730C73 | F30: Yes | G30: Valid | H30: 892.48s
A31: 29 | B31: 00000022.jpg | C31: jpg | D31: 4.83 | E31: 73282D1B51B3A478A5E602BBA22174C500FB82DA2E8A58782B795B39F64740FB | F31: No | G31: False Positive | H31: 892.48s
A32: 30 | B32: 00000023.jpg | C32: jpg | D32: 4.83 | E32: 73282D1B51B3A478A5E602BBA22174C500FB82DA2E8A58782B795B39F64740FB | F32: No | G32: False Positive | H32: 892.48s
A33: 31 | B33: 00000040.mov | C33: mov | D33: 9.54 | E33: 957A28C4FB61A98C0533A07A7386267A747AA9AAF645AC4BF3E1ED632A12B8AC | F33: No | G33: Corrupted | H33: 892.48s
A34: 32 | B34: 00000041.mov | C34: mov | D34: 9.54 | E34: 9DB0A16E0D80306D03DD51C17DA8F44536536574B98CEC4939F8DECC0D5BDCFC | F34: No | G34: False Positive | H34: 892.48s
A35: 33 | B35: 00000042.mov | C35: mov | D35: 9.54 | E35: 670C64DAA146673A32F0B980AAC9375D09A4D6264F6A0480DE9BAE41FB3E889C | F35: No | G35: False Positive | H35: 892.48s
A36: 34 | B36: 00000043.mov | C36: mov | D36: 9.54 | E36: 4FDB903256812CF9CCC36FF23A79012FE3603F9A81AA764A251AE5E34A86E6FD | F36: No | G36: False Positive | H36: 892.48s
... A882: 880 | B882: 00000039.png | C882: png | D882: 0.18 | E882: 9170EF5C07398F0289955A668208844C1A7ECBCEDA1DBB3D80237B513A0C4D90 | F882: No | G882: False Positive | H882: 892.48s

Sheet 7 - Scalpel S2
A1: Scalpel - Scenario 2 - Fragmented Deletion
A2: # | B2: Recovered File Name | C2: File Type | D2: Size (KB/MB) | E2: SHA-256 Hash | F2: Match? (Yes/No) | G2: Status | H2: Processing Time (sec)
A3: 1 | B3: 00000039.bmp | C3: bmp | D3: 0.1 | E3: C479D4F62165A1125429F1F2798FCAFF6592243E719F96F326B6D88FD910B7ED | F3: No | G3: False Positive | H3: 1416.70s
A4: 2 | B4: 00000040.bmp | C4: bmp | D4: 0.1 | E4: 15BF7DFB8FF582B3681CEE725E281E04BEF22301921E839C1EFD1399B1CFD468 | F4: No | G4: False Positive | H4: 1416.70s
A5: 3 | B5: 00000041.bmp | C5: bmp | D5: 0.1 | E5: ADDBE4A57A330839F3CFEC36738E54D9B2E98B3C30BC41072ECF5AA48A95280D | F5: No | G5: False Positive | H5: 1416.70s
A6: 4 | B6: 00000042.bmp | C6: bmp | D6: 0.1 | E6: B6FB5FECD001E452C75406BC419B828D972AC0B71DDBC9018072E00CC052AC50 | F6: No | G6: False Positive | H6: 1416.70s | J6: SUMMARY
A7: 5 | B7: 00000043.bmp | C7: bmp | D7: 0.1 | E7: 2225F7091E4D60A090345BA7D74D6F3BCF1A6A17D8207CD054F62A3DC79A95C0 | F7: No | G7: False Positive | H7: 1416.70s | J7: Total Recovered Files (Ret) | K7: =COUNTA(B:B, "<>") -> 1125
A8: 6 | B8: 00000044.bmp | C8: bmp | D8: 0.1 | E8: B11B518D15F31B149BFD4999D8CA238B4A80C6B3F0492568544785BE5A2E689A | F8: No | G8: False Positive | H8: 1416.70s | J8: Valid Files (RnR) | K8: =COUNTIF(F:F,"Yes") -> 3
A9: 7 | B9: 00000045.bmp | C9: bmp | D9: 0.1 | E9: EBFE2B335C67C3F37D9408FDD2E00F3FE602FB90C6F40673B1E7D1D0648AF73A | F9: No | G9: False Positive | H9: 1416.70s | J9: Corrupted Files | K9: =COUNTIF(G:G,"Corrupted") -> 2
A10: 8 | B10: 00000046.bmp | C10: bmp | D10: 0.1 | E10: 8D614188FE584BB569FD736E92749C461A61E828388F82A802A9352EE4314251 | F10: No | G10: False Positive | H10: 1416.70s | J10: False Positives | K10: =COUNTIF(G:G,"False Positive") -> 1118
A11: 9 | B11: 00000047.bmp | C11: bmp | D11: 0.1 | E11: 2DE31269124A84B871F5AC91C796D1DB40D5783C8292F641BB380F065F1B23EB | F11: No | G11: False Positive | H11: 1416.70s | J11: Processing Time (sec) | K11: =H3 -> 1416.70s
A12: 10 | B12: 00000048.bmp | C12: bmp | D12: 0.1 | E12: DDF25D03AEC3AB77351602EC5A00C011261A4A138FDFDA391E46A9EE7D5F86FE | F12: No | G12: False Positive | H12: 1416.70s
A13: 11 | B13: 00000049.bmp | C13: bmp | D13: 0.1 | E13: 33FFFCB7534B8D5B3E28181551524B8938539FFEB504FB4022E13319BC2F0FDE | F13: No | G13: False Positive | H13: 1416.70s
A14: 12 | B14: 00000050.bmp | C14: bmp | D14: 0.1 | E14: D01D9D1D885B5F93006D9244BE9C54053E4D834666FE8A3462B3E20658FA5A70 | F14: No | G14: False Positive | H14: 1416.70s
A15: 13 | B15: 00000051.bmp | C15: bmp | D15: 0.1 | E15: 77B92DE96EDC8BFF74B4625A3515FAEBB76A91B65BA6A62213C8AB0021846CC6 | F15: No | G15: False Positive | H15: 1416.70s
A16: 14 | B16: 00000052.bmp | C16: bmp | D16: 0.1 | E16: 737D1A1C15966B481783FD851515CE3050D1C5C38EF7B69EF8A0011C374220EC | F16: No | G16: False Positive | H16: 1416.70s
A17: 15 | B17: 00000053.bmp | C17: bmp | D17: 0.1 | E17: 57CA7976A4846D1A62E3585B03031195BD01492D478417383804E267257910EA | F17: No | G17: False Positive | H17: 1416.70s
A18: 16 | B18: 00000054.bmp | C18: bmp | D18: 0.1 | E18: B4B05FB6B5039C7F1BC198CD37DF319F2E51C70C8AE501353705C9D737FDA42E | F18: No | G18: False Positive | H18: 1416.70s
A19: 17 | B19: 00000055.bmp | C19: bmp | D19: 0.1 | E19: E4B8F745C258F5FCEB1EB79A09D574534E527E833E66F8CC09D107AA228D8CC0 | F19: No | G19: False Positive | H19: 1416.70s
A20: 18 | B20: 00000056.bmp | C20: bmp | D20: 0.1 | E20: D9D6B66891BB21F1B98A29761D011A320C7BBCEA4F35987F5098B4A4B0B4DE03 | F20: No | G20: False Positive | H20: 1416.70s
A21: 19 | B21: 00000057.bmp | C21: bmp | D21: 0.1 | E21: BC47AA7F52BF50E551D660D849ABFDAD0CA93B543B61439163476D85CEB3CC6D | F21: No | G21: False Positive | H21: 1416.70s
A22: 20 | B22: 00000058.bmp | C22: bmp | D22: 0.1 | E22: A0BB4FB5871FEF9A4AD8C27FD45EC41F5C0DF6FB7FF62B22F08AA42915A5C1E0 | F22: No | G22: False Positive | H22: 1416.70s
A23: 21 | B23: 00000059.bmp | C23: bmp | D23: 0.1 | E23: 3893D50265993B18011D289DC6467FDB18B8C2E0C87EF9E2FA923F3FF98C6DC0 | F23: No | G23: False Positive | H23: 1416.70s
... A1125: 1124 | B1125: 00001122.zip | C1125: zip | D1125: 0.01 | E1125: 7BB26841776092BCD758F5815D28C77DDF2F5EAC15C232F8D32CD28688E8B02C | F1125: No | G1125: False Positive | H1125: 1416.70s

Sheet 8 - Results Summary
A1: RESULTS SUMMARY - All Tools & Scenarios
A2: Tool | B2: Scenario | C2: Rel (Original) | D2: Ret (Recovered) | E2: RnR (Valid) | F2: Corrupted | G2: False Positives | H2: Processing Time (sec) | I2: Carving Rate (%) | J2: Accuracy (%)
A3: Foremost | B3: Scenario 1 (Normal) | C3: 24 | D3: ='2 - Foremost S1'!K6 -> 28 | E3: ='2 - Foremost S1'!K7 -> 9 | F3: ='2 - Foremost S1'!K8 -> 0 | G3: ='2 - Foremost S1'!K9 -> 18 | H3: ='2 - Foremost S1'!K10 -> 75.37s | I3: =IF(D3>0,E3/C3*100,0) -> 37.5 | J3: =IF(D3>0,E3/D3*100,0) -> 32.142857
A4: Foremost | B4: Scenario 2 (Fragmented) | C4: 24 | D4: ='3 - Foremost S2'!K7 -> 478 | E4: ='3 - Foremost S2'!K8 -> 20 | F4: ='3 - Foremost S2'!K9 -> 0 | G4: ='3 - Foremost S2'!K10 -> 457 | H4: ='3 - Foremost S2'!K11 -> 967.83s | I4: =IF(D4>0,E4/C4*100,0) -> 83.333333 | J4: =IF(D4>0,E4/D4*100,0) -> 4.1841004
A5: PhotoRec | B5: Scenario 1 (Normal) | C5: 24 | D5: ='4 - PhotoRec S1'!K17 -> 992 | E5: ='4 - PhotoRec S1'!K18 -> 23 | F5: ='4 - PhotoRec S1'!K19 -> 1 | G5: ='4 - PhotoRec S1'!K20 -> 964 | H5: ='4 - PhotoRec S1'!K21 -> 957.01s | I5: =IF(D5>0,E5/C5*100,0) -> 95.833333 | J5: =IF(D5>0,E5/D5*100,0) -> 2.3185484
A6: PhotoRec | B6: Scenario 2 (Fragmented) | C6: 24 | D6: ='5 - PhotoRec S2'!K7 -> 962 | E6: ='5 - PhotoRec S2'!K8 -> 20 | F6: ='5 - PhotoRec S2'!K9 -> 1 | G6: ='5 - PhotoRec S2'!K10 -> 937 | H6: ='5 - PhotoRec S2'!K11 -> 2000.06s | I6: =IF(D6>0,E6/C6*100,0) -> 83.333333 | J6: =IF(D6>0,E6/D6*100,0) -> 2.0790021
A7: Scalpel | B7: Scenario 1 (Normal) | C7: 24 | D7: ='6 - Scalpel S1'!K20 -> 882 | E7: ='6 - Scalpel S1'!K21 -> 3 | F7: ='6 - Scalpel S1'!K22 -> 2 | G7: ='6 - Scalpel S1'!K23 -> 875 | H7: ='6 - Scalpel S1'!K24 -> 892.48s | I7: =IF(D7>0,E7/C7*100,0) -> 12.5 | J7: =IF(D7>0,E7/D7*100,0) -> 0.34013605
A8: Scalpel | B8: Scenario 2 (Fragmented) | C8: 24 | D8: ='7 - Scalpel S2'!K7 -> 1125 | E8: ='7 - Scalpel S2'!K8 -> 3 | F8: ='7 - Scalpel S2'!K9 -> 2 | G8: ='7 - Scalpel S2'!K10 -> 1118 | H8: ='7 - Scalpel S2'!K11 -> 1416.70s | I8: =IF(D8>0,E8/C8*100,0) -> 12.5 | J8: =IF(D8>0,E8/D8*100,0) -> 0.26666667
A10: Carving Rate = RnR/Rel×100% | Accuracy = RnR/Ret×100%

Sheet 9 - Per File Type
A1: SUCCESS RATE PER FILE TYPE (%)
A2: File Type | B2: Foremost S1 | C2: Foremost S2 | D2: PhotoRec S1 | E2: PhotoRec S2 | F2: Scalpel S1 | G2: Scalpel S2
A3: JPG | B3: =COUNTIFS('2 - Foremost S1'!C:C,"jpg",'2 - Foremost S1'!F:F,"Yes")/6 -> 0 | C3: =COUNTIFS('3 - Foremost S2'!C:C,"jpg",'3 - Foremost S2'!F:F,"Yes")/6 -> 1 | D3: =COUNTIFS('4 - PhotoRec S1'!C:C,"jpg",'4 - PhotoRec S1'!F:F,"Yes")/6 -> 1 | E3: =COUNTIFS('5 - PhotoRec S2'!C:C,"jpg",'5 - PhotoRec S2'!F:F,"Yes")/6 -> 1 | F3: =COUNTIFS('6 - Scalpel S1'!C:C,"jpg",'6 - Scalpel S1'!F:F,"Yes")/6 -> 0.5 | G3: =COUNTIFS('7 - Scalpel S2'!C:C,"jpg",'7 - Scalpel S2'!F:F,"Yes")/6 -> 0.5
A4: PNG | B4: =COUNTIFS('2 - Foremost S1'!C:C,"png",'2 - Foremost S1'!F:F,"Yes")/4 -> 0.25 | C4: =COUNTIFS('3 - Foremost S2'!C:C,"png",'3 - Foremost S2'!F:F,"Yes")/4 -> 0.25 | D4: =COUNTIFS('4 - PhotoRec S1'!C:C,"png",'4 - PhotoRec S1'!F:F,"Yes")/4 -> 2 | E4: =COUNTIFS('5 - PhotoRec S2'!C:C,"png",'5 - PhotoRec S2'!F:F,"Yes")/4 -> 1 | F4: =COUNTIFS('6 - Scalpel S1'!C:C,"png",'6 - Scalpel S1'!F:F,"Yes")/4 -> 0 | G4: =COUNTIFS('7 - Scalpel S2'!C:C,"png",'7 - Scalpel S2'!F:F,"Yes")/4 -> 0
A5: PDF | B5: =COUNTIFS('2 - Foremost S1'!C:C,"pdf",'2 - Foremost S1'!F:F,"Yes")/4 -> 0.75 | C5: =COUNTIFS('3 - Foremost S2'!C:C,"pdf",'3 - Foremost S2'!F:F,"Yes")/4 -> 0.75 | D5: =COUNTIFS('4 - PhotoRec S1'!C:C,"pdf",'4 - PhotoRec S1'!F:F,"Yes")/4 -> 0.5 | E5: =COUNTIFS('5 - PhotoRec S2'!C:C,"pdf",'5 - PhotoRec S2'!F:F,"Yes")/4 -> 0.75 | F5: =COUNTIFS('6 - Scalpel S1'!C:C,"pdf",'6 - Scalpel S1'!F:F,"Yes")/4 -> 0 | G5: =COUNTIFS('7 - Scalpel S2'!C:C,"pdf",'7 - Scalpel S2'!F:F,"Yes")/4 -> 0
A6: DOCX | B6: =COUNTIFS('2 - Foremost S1'!C:C,"docx",'2 - Foremost S1'!F:F,"Yes")/4 -> 0.5 | C6: =COUNTIFS('3 - Foremost S2'!C:C,"docx",'3 - Foremost S2'!F:F,"Yes")/4 -> 1 | D6: =COUNTIFS('4 - PhotoRec S1'!C:C,"docx",'4 - PhotoRec S1'!F:F,"Yes")/4 -> 0.75 | E6: =COUNTIFS('5 - PhotoRec S2'!C:C,"docx",'5 - PhotoRec S2'!F:F,"Yes")/4 -> 0.75 | F6: =COUNTIFS('6 - Scalpel S1'!C:C,"docx",'6 - Scalpel S1'!F:F,"Yes")/4 -> 0 | G6: =COUNTIFS('7 - Scalpel S2'!C:C,"docx",'7 - Scalpel S2'!F:F,"Yes")/4 -> 0
A7: MP4 | B7: =(COUNTIFS('2 - Foremost S1'!C:C,"*mp4*",'2 - Foremost S1'!F:F,"Yes")+COUNTIFS('2 - Foremost S1'!C:C,"*mov*",'2 - Foremost S1'!F:F,"Yes"))/6 -> 0.5 | C7: =(COUNTIFS('3 - Foremost S2'!C:C,"*mp4*",'3 - Foremost S2'!F:F,"Yes")+COUNTIFS('3 - Foremost S2'!C:C,"*mov*",'3 - Foremost S2'!F:F,"Yes"))/6 -> 1 | D7: =(COUNTIFS('4 - PhotoRec S1'!C:C,"*mp4*",'4 - PhotoRec S1'!F:F,"Yes")+COUNTIFS('4 - PhotoRec S1'!C:C,"*mov*",'4 - PhotoRec S1'!F:F,"Yes"))/6 -> 0.66666667 | E7: =(COUNTIFS('5 - PhotoRec S2'!C:C,"*mp4*",'5 - PhotoRec S2'!F:F,"Yes")+COUNTIFS('5 - PhotoRec S2'!C:C,"*mov*",'5 - PhotoRec S2'!F:F,"Yes"))/6 -> 0.66666667 | F7: =(COUNTIFS('6 - Scalpel S1'!C:C,"*mp4*",'6 - Scalpel S1'!F:F,"Yes")+COUNTIFS('6 - Scalpel S1'!C:C,"*mov*",'6 - Scalpel S1'!F:F,"Yes"))/6 -> 0 | G7: =(COUNTIFS('7 - Scalpel S2'!C:C,"*mp4*",'7 - Scalpel S2'!F:F,"Yes")+COUNTIFS('7 - Scalpel S2'!C:C,"*mov*",'7 - Scalpel S2'!F:F,"Yes"))/6 -> 0
